<?xml version="1.0" encoding="utf-8"?>
<!-- This URDF was automatically created by SolidWorks to URDF Exporter! Originally created by Stephen Brawner (brawner@gmail.com) 
     Commit Version: 1.6.0-1-g15f4949  Build Version: 1.6.7594.29634
     For more information, please see http://wiki.ros.org/sw_urdf_exporter -->
<robot name="AGV"> 

  <link name="base_footprint"/>

  <joint name="base_joint" type="fixed">
    <parent link="base_footprint"/>
    <child link="base_link"/>
    <origin xyz="0.0 0.0 0.0707" rpy="0 0 0"/>
  </joint>


  <link
    name="base_link">
    <inertial>
      <origin
        xyz="-0.000147960478478083 3.47139655930324E-05 -0.00150000000000011"
        rpy="0 0 0" />
      <mass
        value="0.38435995228823" />
      <inertia
        ixx="0.00460412949362981"
        ixy="-1.97418608446194E-09"
        ixz="-7.79835858007088E-19"
        iyy="0.00445919737361735"
        iyz="2.96249984847952E-19"
        izz="0.00906275032731873" />
    </inertial>

    <visual>
      <origin
        xyz="0 0 0"
        rpy="0 0 0" />
      <geometry>
        <mesh
          filename="package://robot_description/meshes/base_link.STL" />
      </geometry>
      <material
        name="">
        <color
          rgba="0.0 0.0 0.0 1" />
      </material>
    </visual>

    <collision>
      <origin
        xyz="0 0 0"
        rpy="0 0 0" />
      <geometry>
        <mesh
          filename="package://robot_description/meshes/base_link.STL" />
      </geometry>
    </collision>
  </link>


  <link
    name="wheel_left_link">
    <inertial>
      <origin
        xyz="-3.99818811628942E-08 0.385619590514504 -1.18655837960668E-07"
        rpy="0 0 0" />
      <mass
        value="0.0496616978661662" />
      <inertia
        ixx="2.03382881443977E-05"
        ixy="-2.23197649799962E-11"
        ixz="5.49796094869999E-11"
        iyy="3.50786037793918E-05"
        iyz="3.55422342984138E-11"
        izz="2.03381249786203E-05" />
    </inertial>

    <visual>
      <origin
        xyz="0 0 0"
        rpy="0 0 0" />
      <geometry>
        <mesh
          filename="package://robot_description/meshes/left_link.STL" />
      </geometry>
      <material
        name="">
        <color
          rgba="0.792156862745098 0.819607843137255 0.933333333333333 1" />
      </material>
    </visual>

    <collision>
      <origin
        xyz="0 0 0"
        rpy="0 0 0" />
      <geometry>
        <mesh
          filename="package://robot_description/meshes/left_link.STL" />
      </geometry>
    </collision>
  </link>


  <joint
    name="wheel_left_joint"
    type="continuous">
    <origin
      xyz="0 -0.186 -0.0387"
      rpy="0 0 0" />
    <parent
      link="base_link" />
    <child
      link="wheel_left_link" />
    <axis
      xyz="0 1 0" />
  </joint>


  <link
    name="wheel_right_link">
    <inertial>
      <origin
        xyz="-1.23757694208339E-07 -0.385619590514504 1.90208277184301E-08"
        rpy="0 0 0" />
      <mass
        value="0.0496616978661661" />
      <inertia
        ixx="2.03382043208664E-05"
        ixy="-2.13091183277867E-11"
        ixz="9.83539765475893E-11"
        iyy="3.50786037793918E-05"
        iyz="3.61572095608502E-11"
        izz="2.03382088021516E-05" />
    </inertial>

    <visual>
      <origin
        xyz="0 0 0"
        rpy="0 0 0" />
      <geometry>
        <mesh
          filename="package://robot_description/meshes/right_link.STL" />
      </geometry>
      <material
        name="">
        <color
          rgba="0.792156862745098 0.819607843137255 0.933333333333333 1" />
      </material>
    </visual>

    <collision>
      <origin
        xyz="0 0 0"
        rpy="0 0 0" />
      <geometry>
        <mesh
          filename="package://robot_description/meshes/right_link.STL" />
      </geometry>
    </collision>
  </link>


  <joint
    name="wheel_right_joint"
    type="continuous">
    <origin
      xyz="0 0.186 -0.0387"
      rpy="0 0 0" />
    <parent
      link="base_link" />
    <child
      link="wheel_right_link" />
    <axis
      xyz="0 1 0" />
  </joint>


  <link
    name="imu_link">
    <inertial>
      <origin
        xyz="-0.20152 -.0019616 -0.0175"
        rpy="0 0 0" />
      <mass
        value="3.64288404677104E-08" />
      <inertia
        ixx="2.33944458101369E-11"
        ixy="2.12048079073072E-13"
        ixz="1.01671768768941E-14"
        iyy="3.4987401662519E-12"
        iyz="1.74566371036128E-15"
        izz="2.35952710883406E-11" />
    </inertial>
    <visual>
      <origin
        xyz="-0.20152 -.0019616 -0.0175"
        rpy="0 0 0" />
      <geometry>
        <mesh
          filename="package://robot_description/meshes/imu_link.STL" />
      </geometry>
      <material
        name="">
        <color
          rgba="0.701960784313725 0.701960784313725 0.701960784313725 1" />
      </material>
    </visual>
    <collision>
      <origin
        xyz="-0.20152 -.0019616 -0.0175"
        rpy="0 0 0" />
      <geometry>
        <mesh
          filename="package://robot_description/meshes/imu_link.STL" />
      </geometry>
    </collision>
  </link>

  
  <joint name="imu_joint" type="fixed">
    <origin
      xyz="0.20152 -0.0019616 0.0175"
      rpy="0 0 0" />
    <parent
      link="base_link" />
    <child
      link="imu_link" />
    <axis
      xyz="0 0 0" />
  </joint>


  <link
    name="base_scan">
    <inertial>
      <origin
        xyz="-0.132 0.0017476 -0.083"
        rpy="0 0 0" />
      <mass
        value="0.166060934057212" />
      <inertia
        ixx="7.69218590206876E-05"
        ixy="-3.96070809302084E-12"
        ixz="2.33735444912028E-07"
        iyy="7.6439713089401E-05"
        iyz="3.8565965123822E-12"
        izz="0.000108595171347802" />
    </inertial>

    <visual>
      <origin
        xyz="-0.132 0.0017476 -0.083"
        rpy="0 0 0" />
      <geometry>
        <mesh
          filename="package://robot_description/meshes/lidar_link.STL" />
      </geometry>
      <material
        name="">
        <color
          rgba="0.792156862745098 0.819607843137255 0.933333333333333 1" />
      </material>
    </visual>

    <collision>
      <origin
        xyz="-0.132 0.0017476 -0.083"
        rpy="0 0 0" />
      <geometry>
        <mesh
          filename="package://robot_description/meshes/lidar_link.STL" />
      </geometry>
    </collision>
  </link>


  <joint
    name="scan_joint"
    type="fixed">
    <origin
      xyz="0.132 -0.0017476 0.083"
      rpy="0 0 0" />
    <parent
      link="base_link" />
    <child
      link="base_scan" />
    <axis
      xyz="0 0 0" />
  </joint>

  <!--=========================gazebo reference/plugin=======================-->
  <gazebo reference="base_link">
    <material>Gazebo/DarkGrey</material>
  </gazebo>

  <gazebo reference="wheel_left_link">
    <mu1>0.1</mu1>
    <mu2>0.1</mu2>
    <kp>500000.0</kp>
    <kd>10.0</kd>
    <minDepth>0.001</minDepth>
    <maxVel>0.22</maxVel>
    <fdir1>1 0 0</fdir1>
  </gazebo>

  <gazebo reference="wheel_right_link">
    <mu1>0.1</mu1>
    <mu2>0.1</mu2>
    <kp>500000.0</kp>
    <kd>10.0</kd>
    <minDepth>0.001</minDepth>
    <maxVel>0.22</maxVel>
    <fdir1>1 0 0</fdir1>
  </gazebo>

  <gazebo>
    <plugin name="AGV_controller" filename="libgazebo_ros_diff_drive.so">
      <commandTopic>cmd_vel</commandTopic>
      <odometryTopic>odom</odometryTopic>
      <odometryFrame>odom</odometryFrame>
      <odometrySource>world</odometrySource>
      <publishOdomTF>true</publishOdomTF>
      <robotBaseFrame>base_footprint</robotBaseFrame>
      <publishWheelTF>false</publishWheelTF>
      <publishTf>true</publishTf>
      <publishWheelJointState>true</publishWheelJointState>
      <legacyMode>false</legacyMode>
      <updateRate>30</updateRate>
      <leftJoint>wheel_left_joint</leftJoint>
      <rightJoint>wheel_right_joint</rightJoint>
      <wheelSeparation>0.372</wheelSeparation>
      <wheelDiameter>0.064</wheelDiameter>
      <wheelAcceleration>1</wheelAcceleration>
      <wheelTorque>10</wheelTorque>
      <rosDebugLevel>na</rosDebugLevel>
    </plugin>
  </gazebo>

   <gazebo reference="base_scan">
    <sensor type="ray" name="rplidarA2_sensor">
      <pose>0 0 0 0 0 0</pose>
      <visualize>false</visualize>
      <update_rate>40</update_rate>
      <ray>
        <scan>
          <horizontal>
            <samples>720</samples>
            <resolution>1</resolution>
            <min_angle>-3.14159265</min_angle>
            <max_angle>3.14159265</max_angle>
          </horizontal>
        </scan>
        <range>
          <min>0.2</min>
          <max>12.0</max>
          <resolution>0.01</resolution>
        </range>
        <noise>
          <type>gaussian</type>
          <mean>0.0</mean>
          <stddev>0.01</stddev>
        </noise>
      </ray>
      <plugin name="gazebo_ros_rplidarA2_controller" filename="libgazebo_ros_laser.so">
        <topicName>scan</topicName>
        <frameName>base_scan</frameName>
      </plugin>
    </sensor>
  </gazebo> 


  

</robot>