<?xml version="1.0" encoding="utf-8"?>
<!-- This URDF was automatically created by SolidWorks to URDF Exporter! Originally created by Stephen Brawner (brawner@gmail.com) 
     Commit Version: 1.6.0-1-g15f4949  Build Version: 1.6.7594.29634
     For more information, please see http://wiki.ros.org/sw_urdf_exporter -->
<robot name="robot_description"> 

  <link name="base_footprint"/>

  <joint name="base_joint" type="fixed">
    <parent link="base_footprint"/>
    <child link="base_link"/>
    <origin xyz="0.0 0.0 0.04" rpy="0 0 0"/>
  </joint>

  <!-- base link -->
  <link name="base_link">

    <inertial>
      <origin
        xyz="1.09282591403144E-05 -0.208443654641338 -0.0148943025021112" rpy="0 0 0" />
      <mass value="1.24979965944518" />
      <inertia
        ixx="0.00486451475924956"
        ixy="3.70495761186734E-09"
        ixz="-7.44118138807528E-11"
        iyy="0.00537090313594017"
        iyz="-2.51200938218995E-05"
        izz="0.00992821992821282" />
    </inertial>

    <visual>
      <origin xyz="0 0 0" rpy="0 0 0" />
      <geometry>
        <mesh filename="package://robot_description/meshes/base_link.stl" />
      </geometry>
      <material name="">
        <color rgba="0.792156862745098 0.819607843137255 0.933333333333333 1" />
      </material>
    </visual>
    <!--you need to change collision range after experiment-->>
    <collision>
      <origin xyz="0 0 0" rpy="0 0 0" />
      <geometry>
        <mesh filename="package://robot_description/meshes/base_link.stl" />
      </geometry>
    </collision>
  </link>

  <!-- lidar -->
  <link name="base_scan">

    <inertial>
      <origin
        xyz="7.89E-09 0.01946 -0.00012848" rpy="0 0 0" />
      <mass value="0.16606" />
      <inertia
        ixx="7.644E-05"
        ixy="3.8566E-12"
        ixz="-3.9607E-12"
        iyy="0.0001086"
        iyz="2.3374E-07"
        izz="7.6922E-05" />
    </inertial>

    <visual>
      <origin xyz="0 0 0" rpy="0 0 0" />
      <geometry>
        <mesh filename="package://robot_description/meshes/lidar.stl" />
      </geometry>
      <material name="">
        <color rgba="0.79216 0.81961 0.93333 1" />
      </material>
    </visual>

    <collision>
      <origin xyz="0 0 0" rpy="0 0 0" />
      <geometry>
        <mesh filename="package://robot_description/meshes/lidar.stl" />
      </geometry>
    </collision>
  </link>


  <joint name="scan_joint" type="fixed">
    <origin xyz="-0.0017476 -0.332 0.086" rpy="1.5708 0 0" />
    <parent link="base_link" />
    <child link="base_scan" />
  </joint>


  <link name="wheel_right_link">
    <inertial>
      <origin xyz="0.01362 1.1941E-07 -3.7685E-08" rpy="0 0 0" />
      <mass value="0.049662" />
      <inertia
        ixx="3.5079E-05"
        ixy="-1.5541E-11"
        ixz="3.8986E-11"
        iyy="2.0338E-05"
        iyz="9.4448E-11"
        izz="2.0338E-05" />
    </inertial>
    <visual>
      <origin xyz="0 0 0" rpy="0 0 0" />
      <geometry>
        <mesh filename="package://robot_description/meshes/right.stl" />
      </geometry>
      <material name="">
        <color rgba="0.79216 0.81961 0.93333 1" />
      </material>
    </visual>
    <collision>
      <origin xyz="0 0 0" rpy="0 0 0" />
      <geometry>
        <mesh filename="package://robot_description/meshes/right.stl" />
      </geometry>
    </collision>
  </link>


  <joint name="wheel_right_joint" type="continuous">
    <origin xyz="-0.186 -0.2 -0.0357" rpy="-0.21892 0 3.1416" />
    <parent link="base_link" />
    <child link="wheel_right_link" />
    <axis xyz="1 0 0" />
  </joint>


  <link name="wheel_left_link">
    <inertial>
      <origin xyz="0 0 0" rpy="0 0 0" />
      <mass value="0" />
      <inertia
        ixx="0"
        ixy="0"
        ixz="0"
        iyy="0"
        iyz="0"
        izz="0" />
    </inertial>
    <visual>
      <origin xyz="0 0 0" rpy="0 0 0" />
      <geometry>
        <mesh filename="package://robot_description/meshes/left.stl" />
      </geometry>
      <material name="">
        <color
          rgba="1 1 1 1" />
      </material>
    </visual>
    <collision>
      <origin xyz="0 0 0" rpy="0 0 0" />
      <geometry>
        <mesh filename="package://robot_description/meshes/left.stl" />
      </geometry>
    </collision>
  </link>


  <joint name="wheel_left_joint" type="continuous">
    <origin xyz="0.186 -0.2 -0.0357" rpy="-1.2852 0 0" />
    <parent link="base_link" />
    <child link="wheel_left_link" />
    <axis xyz="1 0 0" />
  </joint>

  
</robot>
