<?xml version="1.0" encoding="utf-8"?>
<!-- This URDF was automatically created by SolidWorks to URDF Exporter! Originally created by Stephen Brawner (brawner@gmail.com) 
     Commit Version: 1.6.0-1-g15f4949  Build Version: 1.6.7594.29634
     For more information, please see http://wiki.ros.org/sw_urdf_exporter -->
<robot name="AGV"> 

  <link name="base_footprint"/>

  <joint name="base_joint" type="fixed">
    <parent link="base_footprint"/>
    <child link="base_link"/>
    <origin xyz="0.0 0.0 0.0707" rpy="0 0 0"/>
  </joint>


  <link
    name="base_link">
    <inertial>
      <origin
        xyz="0.00233333226458639 7.58157511589364E-05 -0.00568830564416773"
        rpy="0 0 0" />
      <mass
        value="3.83244977936653" />
      <inertia
        ixx="0.0376715877512905"
        ixy="-1.84638335648326E-07"
        ixz="1.52675557200285E-08"
        iyy="0.0361042682027569"
        iyz="-7.35916671700173E-07"
        izz="0.073561130457198" />
    </inertial>

    <visual>
      <origin
        xyz="0 0 0"
        rpy="0 0 0" />
      <geometry>
        <mesh
          filename="package://robot_description/meshes/base_link.STL" />
      </geometry>
      <material
        name="">
        <color
          rgba="0.792156862745098 0.819607843137255 0.933333333333333 1" />
      </material>
    </visual>

    <collision>
      <origin
        xyz="0 0 0"
        rpy="0 0 0" />
      <geometry>
        <mesh
          filename="package://robot_description/meshes/base_link.STL" />
      </geometry>
    </collision>
  </link>


  <link
    name="wheel_left_link">
    <inertial>
      <origin
        xyz="-3.99818811836269E-08 0.385619590514504 -1.18655838099446E-07"
        rpy="0 0 0" />
      <mass
        value="0.0496616978661665" />
      <inertia
        ixx="2.03382881443979E-05"
        ixy="-2.23197649737191E-11"
        ixz="5.49796094612281E-11"
        iyy="3.5078603779392E-05"
        iyz="3.55422343426354E-11"
        izz="2.03381249786204E-05" />
    </inertial>

    <visual>
      <origin
        xyz="0 0 0"
        rpy="0 0 0" />
      <geometry>
        <mesh
          filename="package://robot_description/meshes/left_link.STL" />
      </geometry>
      <material
        name="">
        <color
          rgba="0.792156862745098 0.819607843137255 0.933333333333333 1" />
      </material>
    </visual>

    <collision>
      <origin
        xyz="0 0 0"
        rpy="0 0 0" />
      <geometry>
        <mesh
          filename="package://robot_description/meshes/left_link.STL" />
      </geometry>
    </collision>
  </link>


  <joint
    name="wheel_left_joint"
    type="continuous">
    <origin
      xyz="0 -0.186 -0.0387"
      rpy="0 0 0" />
    <parent
      link="base_link" />
    <child
      link="wheel_left_link" />
    <axis
      xyz="0 1 0" />
  </joint>


  <link
    name="wheel_right_link">
    <inertial>
      <origin
        xyz="-1.23757694347444E-07 -0.385619590514504 1.90208277670023E-08"
        rpy="0 0 0" />
      <mass
        value="0.0496616978661664" />
      <inertia
        ixx="2.03382043208665E-05"
        ixy="-2.13091183699482E-11"
        ixz="9.83539766055479E-11"
        iyy="3.5078603779392E-05"
        iyz="3.61572095755973E-11"
        izz="2.03382088021518E-05" />
    </inertial>

    <visual>
      <origin
        xyz="0 0 0"
        rpy="0 0 0" />
      <geometry>
        <mesh
          filename="package://robot_description/meshes/right_link.STL" />
      </geometry>
      <material
        name="">
        <color
          rgba="0.792156862745098 0.819607843137255 0.933333333333333 1" />
      </material>
    </visual>

    <collision>
      <origin
        xyz="0 0 0"
        rpy="0 0 0" />
      <geometry>
        <mesh
          filename="package://robot_description/meshes/right_link.STL" />
      </geometry>
    </collision>
  </link>


  <joint
    name="wheel_right_joint"
    type="continuous">
    <origin
      xyz="0 0.186 -0.0387"
      rpy="0 0 0" />
    <parent
      link="base_link" />
    <child
      link="wheel_right_link" />
    <axis
      xyz="0 1 0" />
  </joint>


  <link
    name="imu_link">
    <inertial>
      <origin
        xyz="-0.0127336352471249 0.00336693385457607 -2.33042901467487E-05"
        rpy="0 0 0" />
      <mass
        value="3.64288391721299E-08" />
      <inertia
        ixx="2.33944451318896E-11"
        ixy="2.12048018077367E-13"
        ixz="1.01671767574047E-14"
        iyy="3.49874014962155E-12"
        iyz="1.74566413778399E-15"
        izz="2.35952703935789E-11" />
    </inertial>
    <visual>
      <origin
        xyz="0 0 0"
        rpy="0 0 0" />
      <geometry>
        <mesh
          filename="package://robot_description/meshes/imu_link.STL" />
      </geometry>
      <material
        name="">
        <color
          rgba="0.701960784313725 0.701960784313725 0.701960784313725 1" />
      </material>
    </visual>
    <collision>
      <origin
        xyz="0 0 0"
        rpy="0 0 0" />
      <geometry>
        <mesh
          filename="package://robot_description/meshes/imu_link.STL" />
      </geometry>
    </collision>
  </link>


  <joint
    name="imu_joint"
    type="fixed">
    <origin
      xyz="0.20152 -0.0019616 0.0175"
      rpy="0 0 0" />
    <parent
      link="base_link" />
    <child
      link="imu_link" />
    <axis
      xyz="0 0 0" />
  </joint>


  <link
    name="base_scan">
    <inertial>
      <origin
        xyz="-0.00012848195251286 7.88999597557336E-09 0.0194599739289367"
        rpy="0 0 0" />
      <mass
        value="0.166060934057212" />
      <inertia
        ixx="7.69218590206876E-05"
        ixy="-3.9607080925207E-12"
        ixz="2.33735444912028E-07"
        iyy="7.6439713089401E-05"
        iyz="3.85659651278066E-12"
        izz="0.000108595171347802" />
    </inertial>

    <visual>
      <origin
        xyz="0 0 0"
        rpy="0 0 0" />
      <geometry>
        <mesh
          filename="package://robot_description/meshes/lidar_link.STL" />
      </geometry>
      <material
        name="">
        <color
          rgba="0.792156862745098 0.819607843137255 0.933333333333333 1" />
      </material>
    </visual>

    <collision>
      <origin
        xyz="0 0 0"
        rpy="0 0 0" />
      <geometry>
        <mesh
          filename="package://robot_description/meshes/lidar_link.STL" />
      </geometry>
    </collision>
  </link>


  <joint
    name="scan_joint"
    type="fixed">
    <origin
      xyz="0.132 -0.0017476 0.083"
      rpy="0 0 0" />
    <parent
      link="base_link" />
    <child
      link="base_scan" />
    <axis
      xyz="0 0 0" />
  </joint>


  <link
    name="front_rotate_link">
    <inertial>
      <origin
        xyz="-0.0164954514095244 -8.32667268468867E-17 -0.0127446770115047"
        rpy="0 0 0" />
      <mass
        value="0.023917826288437" />
      <inertia
        ixx="8.2007131270127E-06"
        ixy="0"
        ixz="-1.86482418604573E-06"
        iyy="9.0041305189012E-06"
        iyz="-4.49597492003343E-22"
        izz="1.11714136137616E-05" />
    </inertial>

    <visual>
      <origin
        xyz="0 0 0"
        rpy="0 0 0" />
      <geometry>
        <mesh
          filename="package://robot_description/meshes/front_rotate.STL" />
      </geometry>
      <material
        name="">
        <color
          rgba="0.749019607843137 0.749019607843137 0.749019607843137 1" />
      </material>
    </visual>
    
    <collision>
      <origin
        xyz="0 0 0"
        rpy="0 0 0" />
      <geometry>
        <mesh
          filename="package://robot_description/meshes/front_rotate.STL" />
      </geometry>
    </collision>
  </link>


  <joint
    name="front_rotate_joint"
    type="continuous">
    <origin
      xyz="0.1385 0 -0.00985"
      rpy="0 0 1.0273" />
    <parent
      link="base_link" />
    <child
      link="front_rotate_link" />
    <axis
      xyz="0 0 1" />
  </joint>


  <link
    name="front_wheel_link">
    <inertial>
      <origin
        xyz="-1.80411241501588E-16 -1.11022302462516E-16 1.38777878078145E-17"
        rpy="0 0 0" />
      <mass
        value="0.0469863288657831" />
      <inertia
        ixx="9.52959905284745E-06"
        ixy="-4.2351647362715E-21"
        ixz="-1.96470150119616E-21"
        iyy="1.44156278093498E-05"
        iyz="-1.55998282963887E-21"
        izz="9.52959905284745E-06" />
    </inertial>

    <visual>
      <origin
        xyz="0 0 0"
        rpy="0 0 0" />
      <geometry>
        <mesh
          filename="package://robot_description/meshes/front_wheel.STL" />
      </geometry>
      <material
        name="">
        <color
          rgba="0.749019607843137 0.749019607843137 0.749019607843137 1" />
      </material>
    </visual>

    <collision>
      <origin
        xyz="0 0 0"
        rpy="0 0 0" />
      <geometry>
        <mesh
          filename="package://robot_description/meshes/front_wheel.STL" />
      </geometry>
    </collision>
  </link>


  <joint
    name="front_wheel_joint"
    type="continuous">
    <origin
      xyz="-0.033 0 -0.03635"
      rpy="0 0 0" />
    <parent
      link="front_rotate_link" />
    <child
      link="front_wheel_link" />
    <axis
      xyz="0 -1 0" />
  </joint>
  <link
    name="back_rotate_link">
    <inertial>
      <origin
        xyz="0.0164954514095245 0 0.0127446770115048"
        rpy="0 0 0" />
      <mass
        value="0.023917826288437" />
      <inertia
        ixx="8.20071312701268E-06"
        ixy="1.27054942088145E-21"
        ixz="-1.86482418604572E-06"
        iyy="9.00413051890118E-06"
        iyz="-1.28772844257192E-21"
        izz="1.11714136137616E-05" />
    </inertial>

    <visual>
      <origin
        xyz="0 0 0"
        rpy="0 0 0" />
      <geometry>
        <mesh
          filename="package://robot_description/meshes/back_rotate.STL" />
      </geometry>
      <material
        name="">
        <color
          rgba="0.749019607843137 0.749019607843137 0.749019607843137 1" />
      </material>
    </visual>

    <collision>
      <origin
        xyz="0 0 0"
        rpy="0 0 0" />
      <geometry>
        <mesh
          filename="package://robot_description/meshes/back_rotate.STL" />
      </geometry>
    </collision>
  </link>


  <joint
    name="back_rotate_joint"
    type="continuous">
    <origin
      xyz="-0.1385 0 -0.00985"
      rpy="-3.1416 0 -0.20493" />
    <parent
      link="base_link" />
    <child
      link="back_rotate_link" />
    <axis
      xyz="0 0 -1" />
  </joint>


  <link
    name="back_wheel_link">
    <inertial>
      <origin
        xyz="5.55111512312578E-17 -1.38777878078145E-17 1.66533453693773E-16"
        rpy="0 0 0" />
      <mass
        value="0.0469863288657831" />
      <inertia
        ixx="9.52959905284745E-06"
        ixy="-1.05879118406788E-22"
        ixz="-1.8993002353192E-21"
        iyy="1.44156278093498E-05"
        iyz="4.98447024365527E-22"
        izz="9.52959905284745E-06" />
    </inertial>

    <visual>
      <origin
        xyz="0 0 0"
        rpy="0 0 0" />
      <geometry>
        <mesh
          filename="package://robot_description/meshes/back_wheel.STL" />
      </geometry>
      <material
        name="">
        <color
          rgba="0.749019607843137 0.749019607843137 0.749019607843137 1" />
      </material>
    </visual>

    <collision>
      <origin
        xyz="0 0 0"
        rpy="0 0 0" />
      <geometry>
        <mesh
          filename="package://robot_description/meshes/back_wheel.STL" />
      </geometry>
    </collision>
  </link>


  <joint
    name="back_wheel_joint"
    type="continuous">
    <origin
      xyz="0.033 0 0.03635"
      rpy="0 0 0" />
    <parent
      link="back_rotate_link" />
    <child
      link="back_wheel_link" />
    <axis
      xyz="0 -1 0" />
  </joint>

  <!--=========================gazebo reference/plugin=======================-->
  <gazebo reference="base_link">
    <material>Gazebo/DarkGrey</material>
  </gazebo>

  <gazebo reference="wheel_left_link">
    <mu1>0.1</mu1>
    <mu2>0.1</mu2>
    <kp>500000.0</kp>
    <kd>10.0</kd>
    <minDepth>0.001</minDepth>
    <maxVel>0.22</maxVel>
    <fdir1>1 0 0</fdir1>
  </gazebo>

  <gazebo reference="wheel_right_link">
    <mu1>0.1</mu1>
    <mu2>0.1</mu2>
    <kp>500000.0</kp>
    <kd>10.0</kd>
    <minDepth>0.001</minDepth>
    <maxVel>0.22</maxVel>
    <fdir1>1 0 0</fdir1>
  </gazebo>

  <gazebo reference="front_rotate_link">
    <mu1>0.1</mu1>
    <mu2>0.1</mu2>
    <kp>500000.0</kp>
    <kd>10.0</kd>
    <minDepth>0.001</minDepth>
    <maxVel>10</maxVel>
    <fdir1>1 0 0</fdir1>
  </gazebo>

  <gazebo reference="back_rotate_link">
    <mu1>0.1</mu1>
    <mu2>0.1</mu2>
    <kp>500000.0</kp>
    <kd>10.0</kd>
    <minDepth>0.001</minDepth>
    <maxVel>10</maxVel>
    <fdir1>1 0 0</fdir1>
  </gazebo>

  <gazebo reference="front_wheel_link">
    <mu1>0.1</mu1>
    <mu2>0.1</mu2>
    <kp>500000.0</kp>
    <kd>10.0</kd>
    <minDepth>0.001</minDepth>
    <maxVel>0.22</maxVel>
    <fdir1>1 0 0</fdir1>
  </gazebo>

  <gazebo reference="back_wheel_link">
    <mu1>0.1</mu1>
    <mu2>0.1</mu2>
    <kp>500000.0</kp>
    <kd>10.0</kd>
    <minDepth>0.001</minDepth>
    <maxVel>0.22</maxVel>
    <fdir1>1 0 0</fdir1>
  </gazebo>

  <gazebo>
    <plugin name="AGV_controller" filename="libgazebo_ros_diff_drive.so">
      <commandTopic>cmd_vel</commandTopic>
      <odometryTopic>odom</odometryTopic>
      <odometryFrame>odom</odometryFrame>
      <odometrySource>world</odometrySource>
      <publishOdomTF>true</publishOdomTF>
      <robotBaseFrame>base_footprint</robotBaseFrame>
      <publishWheelTF>false</publishWheelTF>
      <publishTf>true</publishTf>
      <publishWheelJointState>true</publishWheelJointState>
      <legacyMode>false</legacyMode>
      <updateRate>30</updateRate>
      <leftJoint>wheel_left_joint</leftJoint>
      <rightJoint>wheel_right_joint</rightJoint>
      <wheelSeparation>0.372</wheelSeparation>
      <wheelDiameter>0.064</wheelDiameter>
      <wheelAcceleration>1</wheelAcceleration>
      <wheelTorque>10</wheelTorque>
      <rosDebugLevel>na</rosDebugLevel>
    </plugin>
  </gazebo>

   <gazebo reference="base_scan">
    <sensor type="ray" name="rplidarA2_sensor">
      <pose>0 0 0 0 0 0</pose>
      <visualize>false</visualize>
      <update_rate>40</update_rate>
      <ray>
        <scan>
          <horizontal>
            <samples>720</samples>
            <resolution>1</resolution>
            <min_angle>-3.14159265</min_angle>
            <max_angle>3.14159265</max_angle>
          </horizontal>
        </scan>
        <range>
          <min>0.2</min>
          <max>12.0</max>
          <resolution>0.01</resolution>
        </range>
        <noise>
          <type>gaussian</type>
          <mean>0.0</mean>
          <stddev>0.01</stddev>
        </noise>
      </ray>
      <plugin name="gazebo_ros_rplidarA2_controller" filename="libgazebo_ros_laser.so">
        <topicName>scan</topicName>
        <frameName>base_scan</frameName>
      </plugin>
    </sensor>
  </gazebo> 


</robot>