<?xml version="1.0" encoding="utf-8"?>
<!-- This URDF was automatically created by SolidWorks to URDF Exporter! Originally created by Stephen Brawner (brawner@gmail.com) 
     Commit Version: 1.6.0-1-g15f4949  Build Version: 1.6.7594.29634
     For more information, please see http://wiki.ros.org/sw_urdf_exporter -->
<robot
  name="urdf02">
  <link
    name="base_link">
    <inertial>
      <origin
        xyz="0.00109242454391657 -2.60058587002593E-05 -0.0128047227127579"
        rpy="0 0 0" />
      <mass
        value="3.47951537357257" />
      <inertia
        ixx="0.0283503032589176"
        ixy="1.40187790352864E-06"
        ixz="-6.43285437919403E-11"
        iyy="0.029742768517206"
        iyz="-1.79370261167301E-11"
        izz="0.0577998837977604" />
    </inertial>
    <visual>
      <origin
        xyz="0 0 0"
        rpy="0 0 0" />
      <geometry>
        <mesh
          filename="package://urdf02/meshes/base_link.STL" />
      </geometry>
      <material
        name="">
        <color
          rgba="0.745098039215686 0.737254901960784 0.729411764705882 1" />
      </material>
    </visual>
    <collision>
      <origin
        xyz="0 0 0"
        rpy="0 0 0" />
      <geometry>
        <mesh
          filename="package://urdf02/meshes/base_link.STL" />
      </geometry>
    </collision>
  </link>
  <link
    name="lidar_link">
    <inertial>
      <origin
        xyz="-0.000127229355419478 1.31350068537095E-07 0.019460782503022"
        rpy="0 0 0" />
      <mass
        value="0.166053843630804" />
      <inertia
        ixx="7.69193007417122E-05"
        ixy="-4.95548703593643E-10"
        ixz="2.37676143504077E-07"
        iyy="7.64310598769666E-05"
        iyz="-2.37005623379629E-10"
        izz="0.000108589049493822" />
    </inertial>
    <visual>
      <origin
        xyz="0 0 0"
        rpy="0 0 0" />
      <geometry>
        <mesh
          filename="package://urdf02/meshes/lidar_link.STL" />
      </geometry>
      <material
        name="">
        <color
          rgba="0.792156862745098 0.819607843137255 0.933333333333333 1" />
      </material>
    </visual>
    <collision>
      <origin
        xyz="0 0 0"
        rpy="0 0 0" />
      <geometry>
        <mesh
          filename="package://urdf02/meshes/lidar_link.STL" />
      </geometry>
    </collision>
  </link>
  <joint
    name="lidar_joint"
    type="fixed">
    <origin
      xyz="0.132 -0.00013082 0.053"
      rpy="0 0 0" />
    <parent
      link="base_link" />
    <child
      link="lidar_link" />
    <axis
      xyz="0 0 0" />
  </joint>
  <link
    name="imu_link">
    <inertial>
      <origin
        xyz="-2.05320786414442E-18 6.93889390390723E-18 0.0125"
        rpy="0 0 0" />
      <mass
        value="0.000289811922293658" />
      <inertia
        ixx="1.57326817116465E-08"
        ixy="0"
        ixz="3.60038419913663E-25"
        iyy="1.57326817116465E-08"
        iyz="-2.54401519141024E-24"
        izz="1.27662151770356E-09" />
    </inertial>
    <visual>
      <origin
        xyz="0 0 0"
        rpy="0 0 0" />
      <geometry>
        <mesh
          filename="package://urdf02/meshes/imu_link.STL" />
      </geometry>
      <material
        name="">
        <color
          rgba="0.749019607843137 0.749019607843137 0.749019607843137 1" />
      </material>
    </visual>
    <collision>
      <origin
        xyz="0 0 0"
        rpy="0 0 0" />
      <geometry>
        <mesh
          filename="package://urdf02/meshes/imu_link.STL" />
      </geometry>
    </collision>
  </link>
  <joint
    name="imu_joint"
    type="continuous">
    <origin
      xyz="0 0 0"
      rpy="0 0 0" />
    <parent
      link="base_link" />
    <child
      link="imu_link" />
    <axis
      xyz="0 0 1" />
  </joint>
  <link
    name="right_link">
    <inertial>
      <origin
        xyz="1.72506873414949E-16 -0.00728844339005699 -2.08166817117217E-17"
        rpy="0 0 0" />
      <mass
        value="0.0848957004604734" />
      <inertia
        ixx="7.4907496519878E-05"
        ixy="-3.29077335789557E-19"
        ixz="-8.56977026080893E-21"
        iyy="0.000130222848529083"
        iyz="7.6497990049025E-22"
        izz="7.4907496519878E-05" />
    </inertial>
    <visual>
      <origin
        xyz="0 0 0"
        rpy="0 0 0" />
      <geometry>
        <mesh
          filename="package://urdf02/meshes/right_link.STL" />
      </geometry>
      <material
        name="">
        <color
          rgba="0.749019607843137 0.749019607843137 0.749019607843137 1" />
      </material>
    </visual>
    <collision>
      <origin
        xyz="0 0 0"
        rpy="0 0 0" />
      <geometry>
        <mesh
          filename="package://urdf02/meshes/right_link.STL" />
      </geometry>
    </collision>
  </link>
  <joint
    name="right_joint"
    type="revolute">
    <origin
      xyz="-0.00016087 -0.16232 -0.0665"
      rpy="0 0 -0.00099109" />
    <parent
      link="base_link" />
    <child
      link="right_link" />
    <axis
      xyz="0 -1 0" />
    <limit
      lower="0"
      upper="0"
      effort="0"
      velocity="0" />
  </joint>
  <link
    name="left_link">
    <inertial>
      <origin
        xyz="9.83472570771662E-18 0.00728844339005719 6.93889390390723E-17"
        rpy="0 0 0" />
      <mass
        value="0.0848957004604736" />
      <inertia
        ixx="7.49074965198782E-05"
        ixy="-4.10033560387089E-20"
        ixz="-1.16910573539205E-20"
        iyy="0.000130222848529084"
        iyz="4.77841065602832E-19"
        izz="7.49074965198782E-05" />
    </inertial>
    <visual>
      <origin
        xyz="0 0 0"
        rpy="0 0 0" />
      <geometry>
        <mesh
          filename="package://urdf02/meshes/left_link.STL" />
      </geometry>
      <material
        name="">
        <color
          rgba="0.749019607843137 0.749019607843137 0.749019607843137 1" />
      </material>
    </visual>
    <collision>
      <origin
        xyz="0 0 0"
        rpy="0 0 0" />
      <geometry>
        <mesh
          filename="package://urdf02/meshes/left_link.STL" />
      </geometry>
    </collision>
  </link>
  <joint
    name="left_joint"
    type="revolute">
    <origin
      xyz="0.00016087 0.16232 -0.0665"
      rpy="0 0 -0.00099109" />
    <parent
      link="base_link" />
    <child
      link="left_link" />
    <axis
      xyz="0 1 0" />
    <limit
      lower="0"
      upper="0"
      effort="0"
      velocity="0" />
  </joint>
  <link
    name="front_link">
    <inertial>
      <origin
        xyz="-0.012247856619052 2.63677968348475E-16 -0.0258423527037026"
        rpy="0 0 0" />
      <mass
        value="0.134968786413858" />
      <inertia
        ixx="0.000132736560537161"
        ixy="2.05670187505185E-20"
        ixz="-1.16913015315812E-05"
        iyy="0.000108905111851544"
        iyz="1.6991854324779E-21"
        izz="0.00016431082681564" />
    </inertial>
    <visual>
      <origin
        xyz="0 0 0"
        rpy="0 0 0" />
      <geometry>
        <mesh
          filename="package://urdf02/meshes/front_link.STL" />
      </geometry>
      <material
        name="">
        <color
          rgba="0.749019607843137 0.749019607843137 0.749019607843137 1" />
      </material>
    </visual>
    <collision>
      <origin
        xyz="0 0 0"
        rpy="0 0 0" />
      <geometry>
        <mesh
          filename="package://urdf02/meshes/front_link.STL" />
      </geometry>
    </collision>
  </link>
  <joint
    name="front_joint"
    type="revolute">
    <origin
      xyz="0.122 -0.00012091 -0.015"
      rpy="0 0 0" />
    <parent
      link="base_link" />
    <child
      link="front_link" />
    <axis
      xyz="0 0 -1" />
    <limit
      lower="0"
      upper="0"
      effort="0"
      velocity="0" />
  </joint>
  <link
    name="f_wheel_link">
    <inertial>
      <origin
        xyz="0 2.70616862252382E-16 -6.93889390390723E-18"
        rpy="0 0 0" />
      <mass
        value="0.192670881607509" />
      <inertia
        ixx="7.63146365292796E-05"
        ixy="1.19769135252778E-19"
        ixz="2.02825221494103E-21"
        iyy="0.00013627319824331"
        iyz="-8.12098592530515E-20"
        izz="7.63146365292795E-05" />
    </inertial>
    <visual>
      <origin
        xyz="0 0 0"
        rpy="0 0 0" />
      <geometry>
        <mesh
          filename="package://urdf02/meshes/f_wheel_link.STL" />
      </geometry>
      <material
        name="">
        <color
          rgba="0.749019607843137 0.749019607843137 0.749019607843137 1" />
      </material>
    </visual>
    <collision>
      <origin
        xyz="0 0 0"
        rpy="0 0 0" />
      <geometry>
        <mesh
          filename="package://urdf02/meshes/f_wheel_link.STL" />
      </geometry>
    </collision>
  </link>
  <joint
    name="f_wheel_joint"
    type="revolute">
    <origin
      xyz="0.019817 0 -0.059"
      rpy="0 0 0" />
    <parent
      link="front_link" />
    <child
      link="f_wheel_link" />
    <axis
      xyz="0 1 0" />
    <limit
      lower="0"
      upper="0"
      effort="0"
      velocity="0" />
  </joint>
  <link
    name="back_link">
    <inertial>
      <origin
        xyz="0.0122478566190519 -2.4980018054066E-16 -0.0258423527037026"
        rpy="0 0 0" />
      <mass
        value="0.134968786413858" />
      <inertia
        ixx="0.000132736560537161"
        ixy="-3.03740720929472E-21"
        ixz="1.16913015315812E-05"
        iyy="0.000108905111851544"
        iyz="1.10029337805242E-20"
        izz="0.00016431082681564" />
    </inertial>
    <visual>
      <origin
        xyz="0 0 0"
        rpy="0 0 0" />
      <geometry>
        <mesh
          filename="package://urdf02/meshes/back_link.STL" />
      </geometry>
      <material
        name="">
        <color
          rgba="0.749019607843137 0.749019607843137 0.749019607843137 1" />
      </material>
    </visual>
    <collision>
      <origin
        xyz="0 0 0"
        rpy="0 0 0" />
      <geometry>
        <mesh
          filename="package://urdf02/meshes/back_link.STL" />
      </geometry>
    </collision>
  </link>
  <joint
    name="back_joint"
    type="revolute">
    <origin
      xyz="-0.122 0.00012091 -0.015"
      rpy="0 0 0" />
    <parent
      link="base_link" />
    <child
      link="back_link" />
    <axis
      xyz="0 0 -1" />
    <limit
      lower="0"
      upper="0"
      effort="0"
      velocity="0" />
  </joint>
  <link
    name="b_wheel_link">
    <inertial>
      <origin
        xyz="0 -2.70616862252382E-16 6.93889390390723E-18"
        rpy="0 0 0" />
      <mass
        value="0.192670881607509" />
      <inertia
        ixx="7.63146365292796E-05"
        ixy="-1.31793032636849E-19"
        ixz="8.50993400127031E-21"
        iyy="0.00013627319824331"
        iyz="-7.98856054603815E-20"
        izz="7.63146365292796E-05" />
    </inertial>
    <visual>
      <origin
        xyz="0 0 0"
        rpy="0 0 0" />
      <geometry>
        <mesh
          filename="package://urdf02/meshes/b_wheel_link.STL" />
      </geometry>
      <material
        name="">
        <color
          rgba="0.749019607843137 0.749019607843137 0.749019607843137 1" />
      </material>
    </visual>
    <collision>
      <origin
        xyz="0 0 0"
        rpy="0 0 0" />
      <geometry>
        <mesh
          filename="package://urdf02/meshes/b_wheel_link.STL" />
      </geometry>
    </collision>
  </link>
  <joint
    name="b_wheel_joint"
    type="revolute">
    <origin
      xyz="-0.019817 0 -0.059"
      rpy="0 0 0" />
    <parent
      link="back_link" />
    <child
      link="b_wheel_link" />
    <axis
      xyz="0 -1 0" />
    <limit
      lower="0"
      upper="0"
      effort="0"
      velocity="0" />
  </joint>
</robot>